Workbook

Sheet Summary
A1: ="How Long Does it Take Each EV to Travel "&TEXT(H2,"###,##0")&" Miles?" -> How Long Does it Take Each EV to Travel 1,000 Miles? | G1: Scenario Parameters | H1: Value | I1: Source
A2: Vehicle | B2: Driving Time | C2: Charging Time | D2: Total Time | E2: Fuel Cost | G2: Driving Distance (Miles) | H2: 1000
A3: Toyota bZ4X | B3: =SUM(INDIRECT("'" & $A3 & "'!$H$24:$H$25")) -> 0.61954365 | C3: {=INDIRECT("'" & $A3 & "'!$H$26")} -> 0.17122407 | D3: {=INDIRECT("'" & $A3 & "'!$H$27")} -> 0.79076772 | E3: {=INDIRECT("'" & $A3 & "'!$G$35")} -> 139.06055 | G3: Charger Detour Distance per Charge (Miles) | H3: 2.5
A4: Ford F-150 Lightning | B4: =SUM(INDIRECT("'" & $A4 & "'!$H$24:$H$25")) -> 0.61954365 | C4: {=INDIRECT("'" & $A4 & "'!$H$26")} -> 0.16081535 | D4: {=INDIRECT("'" & $A4 & "'!$H$27")} -> 0.780359 | E4: {=INDIRECT("'" & $A4 & "'!$G$35")} -> 205.5462 | G4: End of Trip Range (Miles) | H4: 25
A5: Volvo EX30 | B5: =SUM(INDIRECT("'" & $A5 & "'!$H$24:$H$25")) -> 0.61954365 | C5: {=INDIRECT("'" & $A5 & "'!$H$26")} -> 0.12418923 | D5: {=INDIRECT("'" & $A5 & "'!$H$27")} -> 0.74373288 | E5: {=INDIRECT("'" & $A5 & "'!$G$35")} -> 131.93024 | G5: Highway Speed (MPH) | H5: 70
A6: Ford Mustang Mach-e | B6: =SUM(INDIRECT("'" & $A6 & "'!$H$24:$H$25")) -> 0.60912698 | C6: {=INDIRECT("'" & $A6 & "'!$H$26")} -> 0.11996136 | D6: {=INDIRECT("'" & $A6 & "'!$H$27")} -> 0.72908835 | E6: {=INDIRECT("'" & $A6 & "'!$G$35")} -> 123.24094 | G6: City Speed (MPH) | H6: 30
A7: Chevy Equinox | B7: =SUM(INDIRECT("'" & $A7 & "'!$H$24:$H$25")) -> 0.61259921 | C7: {=INDIRECT("'" & $A7 & "'!$H$26")} -> 0.11621988 | D7: {=INDIRECT("'" & $A7 & "'!$H$27")} -> 0.72881908 | E7: {=INDIRECT("'" & $A7 & "'!$G$35")} -> 132.39721 | G7: Start of Trip SoC (%) | H7: 1
A8: Volkswagen ID.4 | B8: =SUM(INDIRECT("'" & $A8 & "'!$H$24:$H$25")) -> 0.61259921 | C8: {=INDIRECT("'" & $A8 & "'!$H$26")} -> 0.093523811 | D8: {=INDIRECT("'" & $A8 & "'!$H$27")} -> 0.70612302 | E8: {=INDIRECT("'" & $A8 & "'!$G$35")} -> 127.67715 | G8: DCFC Beginning SoC (%) | H8: 0.1
A9: Tesla Model Y | B9: =SUM(INDIRECT("'" & $A9 & "'!$H$24:$H$25")) -> 0.60912698 | C9: {=INDIRECT("'" & $A9 & "'!$H$26")} -> 0.082540685 | D9: {=INDIRECT("'" & $A9 & "'!$H$27")} -> 0.69166767 | E9: {=INDIRECT("'" & $A9 & "'!$G$35")} -> 100.62307 | G9: DCFC Ending SoC (%) | H9: 0.8
A10: Hyundai Ioniq 6 | B10: =SUM(INDIRECT("'" & $A10 & "'!$H$24:$H$25")) -> 0.60912698 | C10: {=INDIRECT("'" & $A10 & "'!$H$26")} -> 0.036066101 | D10: {=INDIRECT("'" & $A10 & "'!$H$27")} -> 0.64519308 | E10: {=INDIRECT("'" & $A10 & "'!$G$35")} -> 84.607946 | G10: Home Charging Cost ($/kWh) | H10: 0.1694 | I10: https://www.eia.gov/electricity/monthly/epm_table_grapher.php?t=epmt_5_6_a
G11: DCFC Charging Cost ($/kWh) | H11: 0.46 | I11: https://stable.auto/insights/electric-vehicle-charger-price-by-state
A35: Vehicle | B35: Fuel Cost
A36: Hyundai Ioniq 6 | B36: {=INDIRECT("'" & $A36 & "'!$G$35")} -> 84.607946
A37: Tesla Model Y | B37: {=INDIRECT("'" & $A37 & "'!$G$35")} -> 100.62307
A38: Ford Mustang Mach-e | B38: {=INDIRECT("'" & $A38 & "'!$G$35")} -> 123.24094
A39: Volkswagen ID.4 | B39: {=INDIRECT("'" & $A39 & "'!$G$35")} -> 127.67715
A40: Volvo EX30 | B40: {=INDIRECT("'" & $A40 & "'!$G$35")} -> 131.93024
A41: Chevy Equinox | B41: {=INDIRECT("'" & $A41 & "'!$G$35")} -> 132.39721
A42: Toyota bZ4X | B42: {=INDIRECT("'" & $A42 & "'!$G$35")} -> 139.06055
A43: Ford F-150 Lightning | B43: {=INDIRECT("'" & $A43 & "'!$G$35")} -> 205.5462

Sheet Hyundai Ioniq 6
A1: Battery State of Charge (%) | B1: Charging Speed (kW) | C1: Time (H:MM:SS) | D1: Energy Charged (kWh)
A2: 0 | B2: 50 kW | C2: 0 | D2: 0 kWh | F2: Scenario Parameters | G2: Value | I2: Vehicle Parameters
A3: 0.01 | B3: 205 kW | C3: 0.00025462963 | D3: 0.7 kWh | F3: Driving Distance (Miles) | G3: =Summary!H2 -> 1000 | I3: Vehicle Model | J3: Hyundai Ioniq 6 Long Range RWD
A4: 0.02 | B4: 213 kW | C4: 0.00041666667 | D4: 1.5 kWh | F4: Charger Detour Distance per Charge (Miles) | G4: =Summary!H3 -> 2.5 | I4: ="Vehicle Range @"&G6& "mph - Perfect Condition (Miles)" -> Vehicle Range @70mph - Perfect Condition (Miles) | J4: 324
A5: 0.03 | B5: 215 kW | C5: 0.00056712963 | D5: 2.2 kWh | F5: End of Trip Range (Miles) | G5: =Summary!H4 -> 25 | I5: Range Data Source | J5: https://evkx.net/models/hyundai/ioniq_6/ioniq_6_long_range_rwd/rangeandconsumption/
A6: 0.04 | B6: 215 kW | C6: 0.00071759259 | D6: 3.0 kWh | F6: Highway Speed (MPH) | G6: =Summary!H5 -> 70 | I6: Charging Curve Data Source | J6: https://evkx.net/models/hyundai/ioniq_6/ioniq_6_long_range_rwd/chargingcurve/
A7: 0.05 | B7: 217 kW | C7: 0.00087962963 | D7: 3.7 kWh | F7: City Speed (MPH) | G7: =Summary!H6 -> 30
A8: 0.06 | B8: 218 kW | C8: 0.0010300926 | D8: 4.4 kWh | F8: Start of Trip SoC (%) | G8: =Summary!H7 -> 1 | I8: Key Factors | J8: Values
A9: 0.07 | B9: 219 kW | C9: 0.0011805556 | D9: 5.2 kWh | F9: DCFC Beginning SoC (%) | G9: =Summary!H8 -> 0.1 | I9: =I4 -> Vehicle Range @70mph - Perfect Condition (Miles) | J9: =J4 -> 324
A10: 0.08 | B10: 219 kW | C10: 0.0013310185 | D10: 5.9 kWh | F10: DCFC Ending SoC (%) | G10: =Summary!H9 -> 0.8 | I10: =F38 -> Fuel Efficiency @70mph (Miles/kWh) | J10: =G38 -> 4.3783784
A11: 0.09 | B11: 220 kW | C11: 0.0014814815 | D11: 6.7 kWh | F11: Home Charging Cost ($/kWh) | G11: =Summary!H10 -> 0.1694 | I11: =F42 -> Average Charging Speed 10%-80% (kW) | J11: =G42 -> 204.57746
A12: 0.1 | B12: 221 kW | C12: 0.0016319444 | D12: 7.4 kWh | F12: DCFC Charging Cost ($/kWh) | G12: =Summary!H11 -> 0.46
A13: 0.11 | B13: 221 kW | C13: 0.0017824074 | D13: 8.1 kWh
A14: 0.12 | B14: 222 kW | C14: 0.0019328704 | D14: 8.9 kWh | F14: Time Per Charging Session | G14: Time (Decimal) | H14: Time (Duration)
A15: 0.13 | B15: 222 kW | C15: 0.0020833333 | D15: 9.6 kWh | F15: =TEXT(G9,"00%")&"-"&TEXT(G10,"00%")&" Charging Time" -> 10%-80% Charging Time | G15: =(VLOOKUP(G10,$A$2:$D$102,3,FALSE)-VLOOKUP(G9,$A$2:$D$102,3,FALSE))*24 -> 0.27611111 | H15: =G15/24 -> 0.01150463
A16: 0.14 | B16: 223 kW | C16: 0.0022337963 | D16: 10.4 kWh
A17: 0.15 | B17: 223 kW | C17: 0.0023842593 | D17: 11.1 kWh | F17: Charging Calculations | G17: Value
A18: 0.16 | B18: 222 kW | C18: 0.0025231481 | D18: 11.8 kWh | F18: ="Number of Charges for Driving "&TEXT(G3,"###,##0")&" Miles" -> Number of Charges for Driving 1,000 Miles | G18: =MAX(((G3-(J4*G8))/((J4*(G10-G9)))),0) -> 2.9805996
A19: 0.17 | B19: 223 kW | C19: 0.0026736111 | D19: 12.6 kWh | F19: ="Number of Charges for "&G5&" Miles Remaing" -> Number of Charges for 25 Miles Remaing | G19: =(G5/((J4*(G10-G9)))) -> 0.11022928
A20: 0.18 | B20: 224 kW | C20: 0.0028240741 | D20: 13.3 kWh | F20: Number of Charges for Detour Distance | G20: =IF(SUM((ROUNDUP(G18+G19,0)*(G4/(J4*(G10-G9)))),G18:G19)>ROUNDUP(G18+G19,0),ROUNDUP(G18+G19+1,0)*(G4/(J4*(G10-G9))),ROUNDUP(G18+G19,0)*(G4/(J4*(G10-G9)))) -> 0.044091711
A21: 0.19 | B21: 224 kW | C21: 0.002974537 | D21: 14.1 kWh | F21: Total Number of Charges | G21: =SUM(G18:G20) -> 3.1349206
A22: 0.2 | B22: 224 kW | C22: 0.003125 | D22: 14.8 kWh
A23: 0.21 | B23: 224 kW | C23: 0.0032638889 | D23: 15.5 kWh | F23: Time Results | G23: Time (Decimal) | H23: Time (Duration)
A24: 0.22 | B24: 224 kW | C24: 0.0034143519 | D24: 16.3 kWh | F24: Driving Time | G24: =G3/G6 -> 14.285714 | H24: =G24/24 -> 0.5952381
A25: 0.23 | B25: 225 kW | C25: 0.0035648148 | D25: 17.0 kWh | F25: Charger Detour Driving Time | G25: =ROUNDUP(G21,0)*((G4/G7)) -> 0.33333333 | H25: =G25/24 -> 0.013888889
A26: 0.24 | B26: 225 kW | C26: 0.0037152778 | D26: 17.8 kWh | F26: Charging Time | G26: =G21*G15 -> 0.86558642 | H26: =G26/24 -> 0.036066101
A27: 0.25 | B27: 225 kW | C27: 0.0038657407 | D27: 18.5 kWh | F27: Combined Time | G27: =SUM(G24:G26) -> 15.484634 | H27: =G27/24 -> 0.64519308
A28: 0.26 | B28: 225 kW | C28: 0.0040046296 | D28: 19.2 kWh
A29: 0.27 | B29: 226 kW | C29: 0.0041550926 | D29: 20.0 kWh | F29: Fuel Cost Results | G29: Value
A30: 0.28 | B30: 225 kW | C30: 0.0043055556 | D30: 20.7 kWh | F30: Start of Trip Battery Energy (kWh) | G30: =VALUE(LEFT((VLOOKUP(G8,$A$2:$D$102,4,FALSE)),LEN((VLOOKUP(G8,$A$2:$D$102,4,FALSE)))-4)) -> 74
A31: 0.29 | B31: 226 kW | C31: 0.0044444444 | D31: 21.5 kWh | F31: Energy Recharged per DCFC Session (kWh) | G31: =VALUE(LEFT((VLOOKUP(G10,$A$2:$D$102,4,FALSE)),LEN((VLOOKUP(G10,$A$2:$D$102,4,FALSE)))-4))-VALUE(LEFT((VLOOKUP(G9,$A$2:$D$102,4,FALSE)),LEN((VLOOKUP(G9,$A$2:$D$102,4,FALSE)))-4)) -> 51.8
A32: 0.3 | B32: 226 kW | C32: 0.0045949074 | D32: 22.2 kWh | F32: DCFC Recharged Energy (kWh) | G32: =(G21-G19)*G31 -> 156.67901
A33: 0.31 | B33: 226 kW | C33: 0.0047453704 | D33: 22.9 kWh | F33: Home Charging Cost ($) | G33: =G30*G11 -> 12.5356
A34: 0.32 | B34: 227 kW | C34: 0.0048842593 | D34: 23.7 kWh | F34: DCFC Charging Cost ($) | G34: =G32*G12 -> 72.072346
A35: 0.33 | B35: 227 kW | C35: 0.0050347222 | D35: 24.4 kWh | F35: Total Fuel Costs ($) | G35: =SUM(G33:G34) -> 84.607946
A36: 0.34 | B36: 227 kW | C36: 0.0051851852 | D36: 25.2 kWh
A37: 0.35 | B37: 227 kW | C37: 0.0053240741 | D37: 25.9 kWh | F37: Estimated Fuel Efficiency Results | G37: Value
A38: 0.36 | B38: 230 kW | C38: 0.005474537 | D38: 26.6 kWh | F38: ="Fuel Efficiency @"&$G$6& "mph (Miles/kWh)" -> Fuel Efficiency @70mph (Miles/kWh) | G38: =($J$4*($G$10-$G$9))/$G$31 -> 4.3783784
A39: 0.37 | B39: 230 kW | C39: 0.0056134259 | D39: 27.4 kWh | F39: ="Fuel Efficiency @"&$G$6& "mph (kWh/100 mi)" -> Fuel Efficiency @70mph (kWh/100 mi) | G39: =(1/G38)*100 -> 22.839506
A40: 0.38 | B40: 230 kW | C40: 0.0057638889 | D40: 28.1 kWh
...

Sheet Tesla Model Y
A1: Battery State of Charge (%) | B1: Charging Speed (kW) | C1: Time (H:MM:SS) | D1: Energy Charged (kWh)
A2: 0 | B2: 100 kW | C2: 0 | D2: 0 kWh | F2: Scenario Parameters | G2: Value | I2: Vehicle Parameters
A3: 0.01 | B3: 103 kW | C3: 0.00034722222 | D3: 0.8 kWh | F3: Driving Distance (Miles) | G3: =Summary!H2 -> 1000 | I3: Vehicle Model | J3: Tesla Model Y Long Range
A4: 0.02 | B4: 108 kW | C4: 0.00068287037 | D4: 1.6 kWh | F4: Charger Detour Distance per Charge (Miles) | G4: =Summary!H3 -> 2.5 | I4: ="Vehicle Range @"&G6& "mph - Perfect Condition (Miles)" -> Vehicle Range @70mph - Perfect Condition (Miles) | J4: 297
A5: 0.03 | B5: 108 kW | C5: 0.0010069444 | D5: 2.4 kWh | F5: End of Trip Range (Miles) | G5: =Summary!H4 -> 25 | I5: Range Data Source | J5: https://evkx.net/models/tesla/model_y/model_y_long_range/rangeandconsumption/
A6: 0.04 | B6: 108 kW | C6: 0.0013310185 | D6: 3.2 kWh | F6: Highway Speed (MPH) | G6: =Summary!H5 -> 70 | I6: Charging Curve Data Source | J6: https://evkx.net/models/tesla/model_y/model_y_long_range/chargingcurve/
A7: 0.05 | B7: 108 kW | C7: 0.0016666667 | D7: 4.0 kWh | F7: City Speed (MPH) | G7: =Summary!H6 -> 30
A8: 0.06 | B8: 230 kW | C8: 0.001875 | D8: 4.7 kWh | F8: Start of Trip SoC (%) | G8: =Summary!H7 -> 1 | I8: Key Factors | J8: Values
A9: 0.07 | B9: 235 kW | C9: 0.002025463 | D9: 5.5 kWh | F9: DCFC Beginning SoC (%) | G9: =Summary!H8 -> 0.1 | I9: =I4 -> Vehicle Range @70mph - Perfect Condition (Miles) | J9: =J4 -> 297
A10: 0.08 | B10: 240 kW | C10: 0.0021759259 | D10: 6.3 kWh | F10: DCFC Ending SoC (%) | G10: =Summary!H9 -> 0.8 | I10: =F38 -> Fuel Efficiency @70mph (Miles/kWh) | J10: =G38 -> 3.7594937
A11: 0.09 | B11: 245 kW | C11: 0.0023148148 | D11: 7.1 kWh | F11: Home Charging Cost ($/kWh) | G11: =Summary!H10 -> 0.1694 | I11: =F42 -> Average Charging Speed 10%-80% (kW) | J11: =G42 -> 124.70423
A12: 0.1 | B12: 250 kW | C12: 0.0024652778 | D12: 7.9 kWh | F12: DCFC Charging Cost ($/kWh) | G12: =Summary!H11 -> 0.46
A13: 0.11 | B13: 246 kW | C13: 0.0026041667 | D13: 8.7 kWh
A14: 0.12 | B14: 233 kW | C14: 0.0027546296 | D14: 9.5 kWh | F14: Time Per Charging Session | G14: Time (Decimal) | H14: Time (Duration)
A15: 0.13 | B15: 220 kW | C15: 0.0029050926 | D15: 10.3 kWh | F15: =TEXT(G9,"00%")&"-"&TEXT(G10,"00%")&" Charging Time" -> 10%-80% Charging Time | G15: =(VLOOKUP(G10,$A$2:$D$102,3,FALSE)-VLOOKUP(G9,$A$2:$D$102,3,FALSE))*24 -> 0.55805556 | H15: =G15/24 -> 0.023252315
A16: 0.14 | B16: 211 kW | C16: 0.0030671296 | D16: 11.1 kWh
A17: 0.15 | B17: 200 kW | C17: 0.0032407407 | D17: 11.8 kWh | F17: Charging Calculations | G17: Value
A18: 0.16 | B18: 197 kW | C18: 0.0034259259 | D18: 12.6 kWh | F18: ="Number of Charges for Driving "&TEXT(G3,"###,##0")&" Miles" -> Number of Charges for Driving 1,000 Miles | G18: =MAX(((G3-(J4*G8))/((J4*(G10-G9)))),0) -> 3.3814334
A19: 0.17 | B19: 193 kW | C19: 0.003599537 | D19: 13.4 kWh | F19: ="Number of Charges for "&G5&" Miles Remaing" -> Number of Charges for 25 Miles Remaing | G19: =(G5/((J4*(G10-G9)))) -> 0.12025012
A20: 0.18 | B20: 190 kW | C20: 0.0037847222 | D20: 14.2 kWh | F20: Number of Charges for Detour Distance | G20: =IF(SUM((ROUNDUP(G18+G19,0)*(G4/(J4*(G10-G9)))),G18:G19)>ROUNDUP(G18+G19,0),ROUNDUP(G18+G19+1,0)*(G4/(J4*(G10-G9))),ROUNDUP(G18+G19,0)*(G4/(J4*(G10-G9)))) -> 0.048100048
A21: 0.19 | B21: 188 kW | C21: 0.0039814815 | D21: 15.0 kWh | F21: Total Number of Charges | G21: =SUM(G18:G20) -> 3.5497835
A22: 0.2 | B22: 183 kW | C22: 0.0041666667 | D22: 15.8 kWh
A23: 0.21 | B23: 179 kW | C23: 0.0043634259 | D23: 16.6 kWh | F23: Time Results | G23: Time (Decimal) | H23: Time (Duration)
A24: 0.22 | B24: 175 kW | C24: 0.0045601852 | D24: 17.4 kWh | F24: Driving Time | G24: =G3/G6 -> 14.285714 | H24: =G24/24 -> 0.5952381
A25: 0.23 | B25: 172 kW | C25: 0.0047685185 | D25: 18.2 kWh | F25: Charger Detour Driving Time | G25: =ROUNDUP(G21,0)*((G4/G7)) -> 0.33333333 | H25: =G25/24 -> 0.013888889
A26: 0.24 | B26: 171 kW | C26: 0.0049768519 | D26: 19.0 kWh | F26: Charging Time | G26: =G21*G15 -> 1.9809764 | H26: =G26/24 -> 0.082540685
A27: 0.25 | B27: 167 kW | C27: 0.0051851852 | D27: 19.8 kWh | F27: Combined Time | G27: =SUM(G24:G26) -> 16.600024 | H27: =G27/24 -> 0.69166767
A28: 0.26 | B28: 165 kW | C28: 0.0053935185 | D28: 20.5 kWh
A29: 0.27 | B29: 162 kW | C29: 0.0056134259 | D29: 21.3 kWh | F29: Fuel Cost Results | G29: Value
A30: 0.28 | B30: 159 kW | C30: 0.0058333333 | D30: 22.1 kWh | F30: Start of Trip Battery Energy (kWh) | G30: =VALUE(LEFT((VLOOKUP(G8,$A$2:$D$102,4,FALSE)),LEN((VLOOKUP(G8,$A$2:$D$102,4,FALSE)))-4)) -> 79
A31: 0.29 | B31: 157 kW | C31: 0.0060532407 | D31: 22.9 kWh | F31: Energy Recharged per DCFC Session (kWh) | G31: =VALUE(LEFT((VLOOKUP(G10,$A$2:$D$102,4,FALSE)),LEN((VLOOKUP(G10,$A$2:$D$102,4,FALSE)))-4))-VALUE(LEFT((VLOOKUP(G9,$A$2:$D$102,4,FALSE)),LEN((VLOOKUP(G9,$A$2:$D$102,4,FALSE)))-4)) -> 55.3
A32: 0.3 | B32: 154 kW | C32: 0.0062847222 | D32: 23.7 kWh | F32: DCFC Recharged Energy (kWh) | G32: =(G21-G19)*G31 -> 189.6532
A33: 0.31 | B33: 151 kW | C33: 0.0065162037 | D33: 24.5 kWh | F33: Home Charging Cost ($) | G33: =G30*G11 -> 13.3826
A34: 0.32 | B34: 148 kW | C34: 0.0067476852 | D34: 25.3 kWh | F34: DCFC Charging Cost ($) | G34: =G32*G12 -> 87.240471
A35: 0.33 | B35: 146 kW | C35: 0.0069907407 | D35: 26.1 kWh | F35: Total Fuel Costs ($) | G35: =SUM(G33:G34) -> 100.62307
A36: 0.34 | B36: 143 kW | C36: 0.0072337963 | D36: 26.9 kWh
A37: 0.35 | B37: 139 kW | C37: 0.0074884259 | D37: 27.6 kWh | F37: Estimated Fuel Efficiency Results | G37: Value
A38: 0.36 | B38: 138 kW | C38: 0.0077430556 | D38: 28.4 kWh | F38: ="Fuel Efficiency @"&$G$6& "mph (Miles/kWh)" -> Fuel Efficiency @70mph (Miles/kWh) | G38: =($J$4*($G$10-$G$9))/$G$31 -> 3.7594937
A39: 0.37 | B39: 135 kW | C39: 0.0080092593 | D39: 29.2 kWh | F39: ="Fuel Efficiency @"&$G$6& "mph (kWh/100 mi)" -> Fuel Efficiency @70mph (kWh/100 mi) | G39: =(1/G38)*100 -> 26.599327
A40: 0.38 | B40: 132 kW | C40: 0.008275463 | D40: 30.0 kWh
...

Sheet Chevy Equinox
A1: Battery State of Charge (%) | B1: Charging Speed (kW) | C1: Time (H:MM:SS) | D1: Energy Charged (kWh)
A2: 0 | B2: 50 kW | C2: 0 | D2: 0 kWh | F2: Scenario Parameters | G2: Value | I2: Vehicle Parameters
A3: 0.01 | B3: 60 kW | C3: 0.00068287037 | D3: 0.8 kWh | F3: Driving Distance (Miles) | G3: =Summary!H2 -> 1000 | I3: Vehicle Model | J3: Chevrolet Equinox EV AWD
A4: 0.02 | B4: 70 kW | C4: 0.0012731481 | D4: 1.7 kWh | F4: Charger Detour Distance per Charge (Miles) | G4: =Summary!H3 -> 2.5 | I4: ="Vehicle Range @"&G6& "mph - Perfect Condition (Miles)" -> Vehicle Range @70mph - Perfect Condition (Miles) | J4: 252
A5: 0.03 | B5: 80 kW | C5: 0.0017824074 | D5: 2.6 kWh | F5: End of Trip Range (Miles) | G5: =Summary!H4 -> 25 | I5: Range Data Source | J5: https://evkx.net/models/chevrolet/equinox_ev/equinox_ev_awd/rangeandconsumption/
A6: 0.04 | B6: 90 kW | C6: 0.0022337963 | D6: 3.4 kWh | F6: Highway Speed (MPH) | G6: =Summary!H5 -> 70 | I6: Charging Curve Data Source | J6: https://evkx.net/models/chevrolet/equinox_ev/equinox_ev_awd/chargingcurve/
A7: 0.05 | B7: 100 kW | C7: 0.0026273148 | D7: 4.2 kWh | F7: City Speed (MPH) | G7: =Summary!H6 -> 30
A8: 0.06 | B8: 110 kW | C8: 0.0029861111 | D8: 5.1 kWh | F8: Start of Trip SoC (%) | G8: =Summary!H7 -> 1 | I8: Key Factors | J8: Values
A9: 0.07 | B9: 120 kW | C9: 0.0033217593 | D9: 6.0 kWh | F9: DCFC Beginning SoC (%) | G9: =Summary!H8 -> 0.1 | I9: =I4 -> Vehicle Range @70mph - Perfect Condition (Miles) | J9: =J4 -> 252
A10: 0.08 | B10: 130 kW | C10: 0.0036226852 | D10: 6.8 kWh | F10: DCFC Ending SoC (%) | G10: =Summary!H9 -> 0.8 | I10: =F38 -> Fuel Efficiency @70mph (Miles/kWh) | J10: =G38 -> 2.9647059
A11: 0.09 | B11: 140 kW | C11: 0.003912037 | D11: 7.6 kWh | F11: Home Charging Cost ($/kWh) | G11: =Summary!H10 -> 0.1694 | I11: =F42 -> Average Charging Speed 10%-80% (kW) | J11: =G42 -> 113.01408
A12: 0.1 | B12: 150 kW | C12: 0.0041666667 | D12: 8.5 kWh | F12: DCFC Charging Cost ($/kWh) | G12: =Summary!H11 -> 0.46
A13: 0.11 | B13: 150 kW | C13: 0.0044212963 | D13: 9.4 kWh
A14: 0.12 | B14: 151 kW | C14: 0.0046759259 | D14: 10.2 kWh | F14: Time Per Charging Session | G14: Time (Decimal) | H14: Time (Duration)
A15: 0.13 | B15: 151 kW | C15: 0.0049305556 | D15: 11.0 kWh | F15: =TEXT(G9,"00%")&"-"&TEXT(G10,"00%")&" Charging Time" -> 10%-80% Charging Time | G15: =(VLOOKUP(G10,$A$2:$D$102,3,FALSE)-VLOOKUP(G9,$A$2:$D$102,3,FALSE))*24 -> 0.62638889 | H15: =G15/24 -> 0.026099537
A16: 0.14 | B16: 152 kW | C16: 0.0051851852 | D16: 11.9 kWh
A17: 0.15 | B17: 152 kW | C17: 0.0054282407 | D17: 12.8 kWh | F17: Charging Calculations | G17: Value
A18: 0.16 | B18: 153 kW | C18: 0.0056828704 | D18: 13.6 kWh | F18: ="Number of Charges for Driving "&TEXT(G3,"###,##0")&" Miles" -> Number of Charges for Driving 1,000 Miles | G18: =MAX(((G3-(J4*G8))/((J4*(G10-G9)))),0) -> 4.2403628
A19: 0.17 | B19: 153 kW | C19: 0.0059375 | D19: 14.4 kWh | F19: ="Number of Charges for "&G5&" Miles Remaing" -> Number of Charges for 25 Miles Remaing | G19: =(G5/((J4*(G10-G9)))) -> 0.14172336
A20: 0.18 | B20: 152 kW | C20: 0.0061805556 | D20: 15.3 kWh | F20: Number of Charges for Detour Distance | G20: =IF(SUM((ROUNDUP(G18+G19,0)*(G4/(J4*(G10-G9)))),G18:G19)>ROUNDUP(G18+G19,0),ROUNDUP(G18+G19+1,0)*(G4/(J4*(G10-G9))),ROUNDUP(G18+G19,0)*(G4/(J4*(G10-G9)))) -> 0.070861678
A21: 0.19 | B21: 151 kW | C21: 0.0064351852 | D21: 16.2 kWh | F21: Total Number of Charges | G21: =SUM(G18:G20) -> 4.4529478
A22: 0.2 | B22: 150 kW | C22: 0.0066898148 | D22: 17.0 kWh
A23: 0.21 | B23: 149 kW | C23: 0.0069444444 | D23: 17.8 kWh | F23: Time Results | G23: Time (Decimal) | H23: Time (Duration)
A24: 0.22 | B24: 148 kW | C24: 0.0071990741 | D24: 18.7 kWh | F24: Driving Time | G24: =G3/G6 -> 14.285714 | H24: =G24/24 -> 0.5952381
A25: 0.23 | B25: 148 kW | C25: 0.0074537037 | D25: 19.6 kWh | F25: Charger Detour Driving Time | G25: =ROUNDUP(G21,0)*((G4/G7)) -> 0.41666667 | H25: =G25/24 -> 0.017361111
A26: 0.24 | B26: 147 kW | C26: 0.0077083333 | D26: 20.4 kWh | F26: Charging Time | G26: =G21*G15 -> 2.7892771 | H26: =G26/24 -> 0.11621988
A27: 0.25 | B27: 146 kW | C27: 0.007974537 | D27: 21.2 kWh | F27: Combined Time | G27: =SUM(G24:G26) -> 17.491658 | H27: =G27/24 -> 0.72881908
A28: 0.26 | B28: 145 kW | C28: 0.0082291667 | D28: 22.1 kWh
A29: 0.27 | B29: 144 kW | C29: 0.0084953704 | D29: 23.0 kWh | F29: Fuel Cost Results | G29: Value
A30: 0.28 | B30: 143 kW | C30: 0.0087615741 | D30: 23.8 kWh | F30: Start of Trip Battery Energy (kWh) | G30: =VALUE(LEFT((VLOOKUP(G8,$A$2:$D$102,4,FALSE)),LEN((VLOOKUP(G8,$A$2:$D$102,4,FALSE)))-4)) -> 85
A31: 0.29 | B31: 141 kW | C31: 0.0090277778 | D31: 24.6 kWh | F31: Energy Recharged per DCFC Session (kWh) | G31: =VALUE(LEFT((VLOOKUP(G10,$A$2:$D$102,4,FALSE)),LEN((VLOOKUP(G10,$A$2:$D$102,4,FALSE)))-4))-VALUE(LEFT((VLOOKUP(G9,$A$2:$D$102,4,FALSE)),LEN((VLOOKUP(G9,$A$2:$D$102,4,FALSE)))-4)) -> 59.5
A32: 0.3 | B32: 139 kW | C32: 0.0093055556 | D32: 25.5 kWh | F32: DCFC Recharged Energy (kWh) | G32: =(G21-G19)*G31 -> 256.51786
A33: 0.31 | B33: 137 kW | C33: 0.0095833333 | D33: 26.4 kWh | F33: Home Charging Cost ($) | G33: =G30*G11 -> 14.399
A34: 0.32 | B34: 135 kW | C34: 0.0098611111 | D34: 27.2 kWh | F34: DCFC Charging Cost ($) | G34: =G32*G12 -> 117.99821
A35: 0.33 | B35: 133 kW | C35: 0.010138889 | D35: 28.0 kWh | F35: Total Fuel Costs ($) | G35: =SUM(G33:G34) -> 132.39721
A36: 0.34 | B36: 131 kW | C36: 0.010428241 | D36: 28.9 kWh
A37: 0.35 | B37: 129 kW | C37: 0.010729167 | D37: 29.8 kWh | F37: Estimated Fuel Efficiency Results | G37: Value
A38: 0.36 | B38: 127 kW | C38: 0.011018519 | D38: 30.6 kWh | F38: ="Fuel Efficiency @"&$G$6& "mph (Miles/kWh)" -> Fuel Efficiency @70mph (Miles/kWh) | G38: =($J$4*($G$10-$G$9))/$G$31 -> 2.9647059
A39: 0.37 | B39: 125 kW | C39: 0.011319444 | D39: 31.4 kWh | F39: ="Fuel Efficiency @"&$G$6& "mph (kWh/100 mi)" -> Fuel Efficiency @70mph (kWh/100 mi) | G39: =(1/G38)*100 -> 33.730159
A40: 0.38 | B40: 123 kW | C40: 0.011631944 | D40: 32.3 kWh
...

Sheet Volvo EX30
A1: Battery State of Charge (%) | B1: Charging Speed (kW) | C1: Time (H:MM:SS) | D1: Energy Charged (kWh)
A2: 0 | B2: 20 kW | C2: 0 | D2: 0 kWh | F2: Scenario Parameters | G2: Value | I2: Vehicle Parameters
A3: 0.01 | B3: 30 kW | C3: 0.0011458333 | D3: 0.6 kWh | F3: Driving Distance (Miles) | G3: =Summary!H2 -> 1000 | I3: Vehicle Model | J3: Volvo EX30 Single Motor Extended Range
A4: 0.02 | B4: 33 kW | C4: 0.0020601852 | D4: 1.3 kWh | F4: Charger Detour Distance per Charge (Miles) | G4: =Summary!H3 -> 2.5 | I4: ="Vehicle Range @"&G6& "mph - Perfect Condition (Miles)" -> Vehicle Range @70mph - Perfect Condition (Miles) | J4: 199
A5: 0.03 | B5: 36 kW | C5: 0.0028935185 | D5: 1.9 kWh | F5: End of Trip Range (Miles) | G5: =Summary!H4 -> 25 | I5: Range Data Source | J5: https://evkx.net/models/volvo/ex30/ex30_single_motor_extended_range/rangeandconsumption/
A6: 0.04 | B6: 38 kW | C6: 0.0036689815 | D6: 2.6 kWh | F6: Highway Speed (MPH) | G6: =Summary!H5 -> 70 | I6: Charging Curve Data Source | J6: https://evkx.net/models/volvo/ex30/ex30_single_motor_extended_range/chargingcurve/
A7: 0.05 | B7: 41 kW | C7: 0.0043865741 | D7: 3.2 kWh | F7: City Speed (MPH) | G7: =Summary!H6 -> 30
A8: 0.06 | B8: 44 kW | C8: 0.0050694444 | D8: 3.8 kWh | F8: Start of Trip SoC (%) | G8: =Summary!H7 -> 1 | I8: Key Factors | J8: Values
A9: 0.07 | B9: 47 kW | C9: 0.0056944444 | D9: 4.5 kWh | F9: DCFC Beginning SoC (%) | G9: =Summary!H8 -> 0.1 | I9: =I4 -> Vehicle Range @70mph - Perfect Condition (Miles) | J9: =J4 -> 199
A10: 0.08 | B10: 49 kW | C10: 0.0062962963 | D10: 5.1 kWh | F10: DCFC Ending SoC (%) | G10: =Summary!H9 -> 0.8 | I10: =F38 -> Fuel Efficiency @70mph (Miles/kWh) | J10: =G38 -> 3.109375
A11: 0.09 | B11: 52 kW | C11: 0.0068634259 | D11: 5.8 kWh | F11: Home Charging Cost ($/kWh) | G11: =Summary!H10 -> 0.1694 | I11: =F42 -> Average Charging Speed 10%-80% (kW) | J11: =G42 -> 110.40845
A12: 0.1 | B12: 55 kW | C12: 0.0073958333 | D12: 6.4 kWh | F12: DCFC Charging Cost ($/kWh) | G12: =Summary!H11 -> 0.46
A13: 0.11 | B13: 60 kW | C13: 0.0078935185 | D13: 7.0 kWh
A14: 0.12 | B14: 148 kW | C14: 0.0081712963 | D14: 7.7 kWh | F14: Time Per Charging Session | G14: Time (Decimal) | H14: Time (Duration)
A15: 0.13 | B15: 153 kW | C15: 0.0083564815 | D15: 8.3 kWh | F15: =TEXT(G9,"00%")&"-"&TEXT(G10,"00%")&" Charging Time" -> 10%-80% Charging Time | G15: =(VLOOKUP(G10,$A$2:$D$102,3,FALSE)-VLOOKUP(G9,$A$2:$D$102,3,FALSE))*24 -> 0.49222222 | H15: =G15/24 -> 0.020509259
A16: 0.14 | B16: 153 kW | C16: 0.0085532407 | D16: 9.0 kWh
A17: 0.15 | B17: 154 kW | C17: 0.0087384259 | D17: 9.6 kWh | F17: Charging Calculations | G17: Value
A18: 0.16 | B18: 154 kW | C18: 0.0089236111 | D18: 10.2 kWh | F18: ="Number of Charges for Driving "&TEXT(G3,"###,##0")&" Miles" -> Number of Charges for Driving 1,000 Miles | G18: =MAX(((G3-(J4*G8))/((J4*(G10-G9)))),0) -> 5.7501795
A19: 0.17 | B19: 155 kW | C19: 0.0091087963 | D19: 10.9 kWh | F19: ="Number of Charges for "&G5&" Miles Remaing" -> Number of Charges for 25 Miles Remaing | G19: =(G5/((J4*(G10-G9)))) -> 0.17946877
A20: 0.18 | B20: 155 kW | C20: 0.0092939815 | D20: 11.5 kWh | F20: Number of Charges for Detour Distance | G20: =IF(SUM((ROUNDUP(G18+G19,0)*(G4/(J4*(G10-G9)))),G18:G19)>ROUNDUP(G18+G19,0),ROUNDUP(G18+G19+1,0)*(G4/(J4*(G10-G9))),ROUNDUP(G18+G19,0)*(G4/(J4*(G10-G9)))) -> 0.12562814
A21: 0.19 | B21: 155 kW | C21: 0.0094791667 | D21: 12.2 kWh | F21: Total Number of Charges | G21: =SUM(G18:G20) -> 6.0552764
A22: 0.2 | B22: 155 kW | C22: 0.0096643519 | D22: 12.8 kWh
A23: 0.21 | B23: 156 kW | C23: 0.009849537 | D23: 13.4 kWh | F23: Time Results | G23: Time (Decimal) | H23: Time (Duration)
A24: 0.22 | B24: 156 kW | C24: 0.010034722 | D24: 14.1 kWh | F24: Driving Time | G24: =G3/G6 -> 14.285714 | H24: =G24/24 -> 0.5952381
A25: 0.23 | B25: 157 kW | C25: 0.010208333 | D25: 14.7 kWh | F25: Charger Detour Driving Time | G25: =ROUNDUP(G21,0)*((G4/G7)) -> 0.58333333 | H25: =G25/24 -> 0.024305556
A26: 0.24 | B26: 157 kW | C26: 0.010393519 | D26: 15.4 kWh | F26: Charging Time | G26: =G21*G15 -> 2.9805416 | H26: =G26/24 -> 0.12418923
A27: 0.25 | B27: 157 kW | C27: 0.010578704 | D27: 16.0 kWh | F27: Combined Time | G27: =SUM(G24:G26) -> 17.849589 | H27: =G27/24 -> 0.74373288
A28: 0.26 | B28: 157 kW | C28: 0.010763889 | D28: 16.6 kWh
A29: 0.27 | B29: 157 kW | C29: 0.010949074 | D29: 17.3 kWh | F29: Fuel Cost Results | G29: Value
A30: 0.28 | B30: 157 kW | C30: 0.011122685 | D30: 17.9 kWh | F30: Start of Trip Battery Energy (kWh) | G30: =VALUE(LEFT((VLOOKUP(G8,$A$2:$D$102,4,FALSE)),LEN((VLOOKUP(G8,$A$2:$D$102,4,FALSE)))-4)) -> 64
A31: 0.29 | B31: 157 kW | C31: 0.01130787 | D31: 18.6 kWh | F31: Energy Recharged per DCFC Session (kWh) | G31: =VALUE(LEFT((VLOOKUP(G10,$A$2:$D$102,4,FALSE)),LEN((VLOOKUP(G10,$A$2:$D$102,4,FALSE)))-4))-VALUE(LEFT((VLOOKUP(G9,$A$2:$D$102,4,FALSE)),LEN((VLOOKUP(G9,$A$2:$D$102,4,FALSE)))-4)) -> 44.8
A32: 0.3 | B32: 157 kW | C32: 0.011493056 | D32: 19.2 kWh | F32: DCFC Recharged Energy (kWh) | G32: =(G21-G19)*G31 -> 263.23618
A33: 0.31 | B33: 157 kW | C33: 0.011678241 | D33: 19.8 kWh | F33: Home Charging Cost ($) | G33: =G30*G11 -> 10.8416
A34: 0.32 | B34: 157 kW | C34: 0.011851852 | D34: 20.5 kWh | F34: DCFC Charging Cost ($) | G34: =G32*G12 -> 121.08864
A35: 0.33 | B35: 157 kW | C35: 0.012037037 | D35: 21.1 kWh | F35: Total Fuel Costs ($) | G35: =SUM(G33:G34) -> 131.93024
A36: 0.34 | B36: 143 kW | C36: 0.012233796 | D36: 21.8 kWh
A37: 0.35 | B37: 143 kW | C37: 0.012430556 | D37: 22.4 kWh | F37: Estimated Fuel Efficiency Results | G37: Value
A38: 0.36 | B38: 143 kW | C38: 0.012627315 | D38: 23.0 kWh | F38: ="Fuel Efficiency @"&$G$6& "mph (Miles/kWh)" -> Fuel Efficiency @70mph (Miles/kWh) | G38: =($J$4*($G$10-$G$9))/$G$31 -> 3.109375
A39: 0.37 | B39: 144 kW | C39: 0.012835648 | D39: 23.7 kWh | F39: ="Fuel Efficiency @"&$G$6& "mph (kWh/100 mi)" -> Fuel Efficiency @70mph (kWh/100 mi) | G39: =(1/G38)*100 -> 32.160804
A40: 0.38 | B40: 144 kW | C40: 0.013032407 | D40: 24.3 kWh
...

Sheet Volkswagen ID.4
A1: Battery State of Charge (%) | B1: Charging Speed (kW) | C1: Time (H:MM:SS) | D1: Energy Charged (kWh)
A2: 0 | B2: 50 kW | C2: 0 | D2: 0 kWh | F2: Scenario Parameters | G2: Value | I2: Vehicle Parameters
A3: 0.01 | B3: 131 kW | C3: 0.00037037037 | D3: 0.8 kWh | F3: Driving Distance (Miles) | G3: =Summary!H2 -> 1000 | I3: Vehicle Model | J3: Volkswagen ID.4 Pro
A4: 0.02 | B4: 131 kW | C4: 0.00063657407 | D4: 1.5 kWh | F4: Charger Detour Distance per Charge (Miles) | G4: =Summary!H3 -> 2.5 | I4: ="Vehicle Range @"&G6& "mph - Perfect Condition (Miles)" -> Vehicle Range @70mph - Perfect Condition (Miles) | J4: 239
A5: 0.03 | B5: 131 kW | C5: 0.00090277778 | D5: 2.3 kWh | F5: End of Trip Range (Miles) | G5: =Summary!H4 -> 25 | I5: Range Data Source | J5: https://evkx.net/models/volkswagen/id.4/id.4_pro/rangeandconsumption/
A6: 0.04 | B6: 131 kW | C6: 0.0011689815 | D6: 3.1 kWh | F6: Highway Speed (MPH) | G6: =Summary!H5 -> 70 | I6: Charging Curve Data Source | J6: https://evkx.net/models/volkswagen/id.4/id.4_pro/chargingcurve/
A7: 0.05 | B7: 131 kW | C7: 0.0014236111 | D7: 3.8 kWh | F7: City Speed (MPH) | G7: =Summary!H6 -> 30
A8: 0.06 | B8: 132 kW | C8: 0.0016898148 | D8: 4.6 kWh | F8: Start of Trip SoC (%) | G8: =Summary!H7 -> 1 | I8: Key Factors | J8: Values
A9: 0.07 | B9: 132 kW | C9: 0.0019560185 | D9: 5.4 kWh | F9: DCFC Beginning SoC (%) | G9: =Summary!H8 -> 0.1 | I9: =I4 -> Vehicle Range @70mph - Perfect Condition (Miles) | J9: =J4 -> 239
A10: 0.08 | B10: 132 kW | C10: 0.0022106481 | D10: 6.2 kWh | F10: DCFC Ending SoC (%) | G10: =Summary!H9 -> 0.8 | I10: =F38 -> Fuel Efficiency @70mph (Miles/kWh) | J10: =G38 -> 3.1038961
A11: 0.09 | B11: 133 kW | C11: 0.0024768519 | D11: 6.9 kWh | F11: Home Charging Cost ($/kWh) | G11: =Summary!H10 -> 0.1694 | I11: =F42 -> Average Charging Speed 10%-80% (kW) | J11: =G42 -> 125.04225
A12: 0.1 | B12: 136 kW | C12: 0.0027314815 | D12: 7.7 kWh | F12: DCFC Charging Cost ($/kWh) | G12: =Summary!H11 -> 0.46
A13: 0.11 | B13: 137 kW | C13: 0.0029861111 | D13: 8.5 kWh
A14: 0.12 | B14: 138 kW | C14: 0.0032291667 | D14: 9.2 kWh | F14: Time Per Charging Session | G14: Time (Decimal) | H14: Time (Duration)
A15: 0.13 | B15: 138 kW | C15: 0.0034837963 | D15: 10.0 kWh | F15: =TEXT(G9,"00%")&"-"&TEXT(G10,"00%")&" Charging Time" -> 10%-80% Charging Time | G15: =(VLOOKUP(G10,$A$2:$D$102,3,FALSE)-VLOOKUP(G9,$A$2:$D$102,3,FALSE))*24 -> 0.47027778 | H15: =G15/24 -> 0.019594907
A16: 0.14 | B16: 138 kW | C16: 0.0037384259 | D16: 10.8 kWh
A17: 0.15 | B17: 140 kW | C17: 0.0039814815 | D17: 11.6 kWh | F17: Charging Calculations | G17: Value
A18: 0.16 | B18: 141 kW | C18: 0.004224537 | D18: 12.3 kWh | F18: ="Number of Charges for Driving "&TEXT(G3,"###,##0")&" Miles" -> Number of Charges for Driving 1,000 Miles | G18: =MAX(((G3-(J4*G8))/((J4*(G10-G9)))),0) -> 4.5487149
A19: 0.17 | B19: 140 kW | C19: 0.0044791667 | D19: 13.1 kWh | F19: ="Number of Charges for "&G5&" Miles Remaing" -> Number of Charges for 25 Miles Remaing | G19: =(G5/((J4*(G10-G9)))) -> 0.14943216
A20: 0.18 | B20: 140 kW | C20: 0.0047222222 | D20: 13.9 kWh | F20: Number of Charges for Detour Distance | G20: =IF(SUM((ROUNDUP(G18+G19,0)*(G4/(J4*(G10-G9)))),G18:G19)>ROUNDUP(G18+G19,0),ROUNDUP(G18+G19+1,0)*(G4/(J4*(G10-G9))),ROUNDUP(G18+G19,0)*(G4/(J4*(G10-G9)))) -> 0.074716079
A21: 0.19 | B21: 139 kW | C21: 0.0049652778 | D21: 14.6 kWh | F21: Total Number of Charges | G21: =SUM(G18:G20) -> 4.7728631
A22: 0.2 | B22: 138 kW | C22: 0.0052199074 | D22: 15.4 kWh
A23: 0.21 | B23: 137 kW | C23: 0.005462963 | D23: 16.2 kWh | F23: Time Results | G23: Time (Decimal) | H23: Time (Duration)
A24: 0.22 | B24: 138 kW | C24: 0.0057175926 | D24: 16.9 kWh | F24: Driving Time | G24: =G3/G6 -> 14.285714 | H24: =G24/24 -> 0.5952381
A25: 0.23 | B25: 139 kW | C25: 0.0059722222 | D25: 17.7 kWh | F25: Charger Detour Driving Time | G25: =ROUNDUP(G21,0)*((G4/G7)) -> 0.41666667 | H25: =G25/24 -> 0.017361111
A26: 0.24 | B26: 138 kW | C26: 0.0062152778 | D26: 18.5 kWh | F26: Charging Time | G26: =G21*G15 -> 2.2445715 | H26: =G26/24 -> 0.093523811
A27: 0.25 | B27: 139 kW | C27: 0.0064699074 | D27: 19.2 kWh | F27: Combined Time | G27: =SUM(G24:G26) -> 16.946952 | H27: =G27/24 -> 0.70612302
A28: 0.26 | B28: 138 kW | C28: 0.006712963 | D28: 20.0 kWh
A29: 0.27 | B29: 138 kW | C29: 0.0069675926 | D29: 20.8 kWh | F29: Fuel Cost Results | G29: Value
A30: 0.28 | B30: 138 kW | C30: 0.0072106481 | D30: 21.6 kWh | F30: Start of Trip Battery Energy (kWh) | G30: =VALUE(LEFT((VLOOKUP(G8,$A$2:$D$102,4,FALSE)),LEN((VLOOKUP(G8,$A$2:$D$102,4,FALSE)))-4)) -> 77
A31: 0.29 | B31: 137 kW | C31: 0.0074652778 | D31: 22.3 kWh | F31: Energy Recharged per DCFC Session (kWh) | G31: =VALUE(LEFT((VLOOKUP(G10,$A$2:$D$102,4,FALSE)),LEN((VLOOKUP(G10,$A$2:$D$102,4,FALSE)))-4))-VALUE(LEFT((VLOOKUP(G9,$A$2:$D$102,4,FALSE)),LEN((VLOOKUP(G9,$A$2:$D$102,4,FALSE)))-4)) -> 53.9
A32: 0.3 | B32: 137 kW | C32: 0.0077199074 | D32: 23.1 kWh | F32: DCFC Recharged Energy (kWh) | G32: =(G21-G19)*G31 -> 249.20293
A33: 0.31 | B33: 135 kW | C33: 0.007974537 | D33: 23.9 kWh | F33: Home Charging Cost ($) | G33: =G30*G11 -> 13.0438
A34: 0.32 | B34: 135 kW | C34: 0.0082291667 | D34: 24.6 kWh | F34: DCFC Charging Cost ($) | G34: =G32*G12 -> 114.63335
A35: 0.33 | B35: 135 kW | C35: 0.0084837963 | D35: 25.4 kWh | F35: Total Fuel Costs ($) | G35: =SUM(G33:G34) -> 127.67715
A36: 0.34 | B36: 135 kW | C36: 0.0087384259 | D36: 26.2 kWh
A37: 0.35 | B37: 136 kW | C37: 0.0089930556 | D37: 27.0 kWh | F37: Estimated Fuel Efficiency Results | G37: Value
A38: 0.36 | B38: 136 kW | C38: 0.0092476852 | D38: 27.7 kWh | F38: ="Fuel Efficiency @"&$G$6& "mph (Miles/kWh)" -> Fuel Efficiency @70mph (Miles/kWh) | G38: =($J$4*($G$10-$G$9))/$G$31 -> 3.1038961
A39: 0.37 | B39: 136 kW | C39: 0.0095023148 | D39: 28.5 kWh | F39: ="Fuel Efficiency @"&$G$6& "mph (kWh/100 mi)" -> Fuel Efficiency @70mph (kWh/100 mi) | G39: =(1/G38)*100 -> 32.217573
A40: 0.38 | B40: 139 kW | C40: 0.0097453704 | D40: 29.3 kWh
...

Sheet Ford Mustang Mach-e
A1: Battery State of Charge (%) | B1: Charging Speed (kW) | C1: Time (H:MM:SS) | D1: Energy Charged (kWh)
A2: 0 | B2: 50 kW | C2: 0 | D2: 0 kWh | F2: Scenario Parameters | G2: Value | I2: Vehicle Parameters
A3: 0.01 | B3: 58 kW | C3: 0.00075231481 | D3: 0.9 kWh | F3: Driving Distance (Miles) | G3: =Summary!H2 -> 1000 | I3: Vehicle Model | J3: Ford Mustang Mach-E Long Range AWD
A4: 0.02 | B4: 66 kW | C4: 0.0014236111 | D4: 1.8 kWh | F4: Charger Detour Distance per Charge (Miles) | G4: =Summary!H3 -> 2.5 | I4: ="Vehicle Range @"&G6& "mph - Perfect Condition (Miles)" -> Vehicle Range @70mph - Perfect Condition (Miles) | J4: 285
A5: 0.03 | B5: 74 kW | C5: 0.0020138889 | D5: 2.8 kWh | F5: End of Trip Range (Miles) | G5: =Summary!H4 -> 25 | I5: Range Data Source | J5: https://evkx.net/models/ford/mustang_mach-e/mustang_mach-e_long_range_awd/rangeandconsumption/
A6: 0.04 | B6: 82 kW | C6: 0.0025347222 | D6: 3.7 kWh | F6: Highway Speed (MPH) | G6: =Summary!H5 -> 70 | I6: Charging Curve Data Source | J6: https://evkx.net/models/ford/mustang_mach-e/mustang_mach-e_long_range_awd/chargingcurve/
A7: 0.05 | B7: 90 kW | C7: 0.0030208333 | D7: 4.6 kWh | F7: City Speed (MPH) | G7: =Summary!H6 -> 30
A8: 0.06 | B8: 98 kW | C8: 0.0034606481 | D8: 5.5 kWh | F8: Start of Trip SoC (%) | G8: =Summary!H7 -> 1 | I8: Key Factors | J8: Values
A9: 0.07 | B9: 106 kW | C9: 0.0038657407 | D9: 6.4 kWh | F9: DCFC Beginning SoC (%) | G9: =Summary!H8 -> 0.1 | I9: =I4 -> Vehicle Range @70mph - Perfect Condition (Miles) | J9: =J4 -> 285
A10: 0.08 | B10: 114 kW | C10: 0.0042361111 | D10: 7.4 kWh | F10: DCFC Ending SoC (%) | G10: =Summary!H9 -> 0.8 | I10: =F38 -> Fuel Efficiency @70mph (Miles/kWh) | J10: =G38 -> 3.0978261
A11: 0.09 | B11: 122 kW | C11: 0.0045833333 | D11: 8.3 kWh | F11: Home Charging Cost ($/kWh) | G11: =Summary!H10 -> 0.1694 | I11: =F42 -> Average Charging Speed 10%-80% (kW) | J11: =G42 -> 94.253521
A12: 0.1 | B12: 130 kW | C12: 0.0049074074 | D12: 9.2 kWh | F12: DCFC Charging Cost ($/kWh) | G12: =Summary!H11 -> 0.46
A13: 0.11 | B13: 131 kW | C13: 0.0052314815 | D13: 10.1 kWh
A14: 0.12 | B14: 132 kW | C14: 0.0055439815 | D14: 11.0 kWh | F14: Time Per Charging Session | G14: Time (Decimal) | H14: Time (Duration)
A15: 0.13 | B15: 133 kW | C15: 0.0058564815 | D15: 12.0 kWh | F15: =TEXT(G9,"00%")&"-"&TEXT(G10,"00%")&" Charging Time" -> 10%-80% Charging Time | G15: =(VLOOKUP(G10,$A$2:$D$102,3,FALSE)-VLOOKUP(G9,$A$2:$D$102,3,FALSE))*24 -> 0.76583333 | H15: =G15/24 -> 0.031909722
A16: 0.14 | B16: 136 kW | C16: 0.0061574074 | D16: 12.9 kWh
A17: 0.15 | B17: 139 kW | C17: 0.0064583333 | D17: 13.8 kWh | F17: Charging Calculations | G17: Value
A18: 0.16 | B18: 143 kW | C18: 0.0067476852 | D18: 14.7 kWh | F18: ="Number of Charges for Driving "&TEXT(G3,"###,##0")&" Miles" -> Number of Charges for Driving 1,000 Miles | G18: =MAX(((G3-(J4*G8))/((J4*(G10-G9)))),0) -> 3.5839599
A19: 0.17 | B19: 118 kW | C19: 0.0070717593 | D19: 15.6 kWh | F19: ="Number of Charges for "&G5&" Miles Remaing" -> Number of Charges for 25 Miles Remaing | G19: =(G5/((J4*(G10-G9)))) -> 0.12531328
A20: 0.18 | B20: 111 kW | C20: 0.0074305556 | D20: 16.6 kWh | F20: Number of Charges for Detour Distance | G20: =IF(SUM((ROUNDUP(G18+G19,0)*(G4/(J4*(G10-G9)))),G18:G19)>ROUNDUP(G18+G19,0),ROUNDUP(G18+G19+1,0)*(G4/(J4*(G10-G9))),ROUNDUP(G18+G19,0)*(G4/(J4*(G10-G9)))) -> 0.050125313
A21: 0.19 | B21: 111 kW | C21: 0.0078009259 | D21: 17.5 kWh | F21: Total Number of Charges | G21: =SUM(G18:G20) -> 3.7593985
A22: 0.2 | B22: 112 kW | C22: 0.0081712963 | D22: 18.4 kWh
A23: 0.21 | B23: 112 kW | C23: 0.0085416667 | D23: 19.3 kWh | F23: Time Results | G23: Time (Decimal) | H23: Time (Duration)
A24: 0.22 | B24: 111 kW | C24: 0.008900463 | D24: 20.2 kWh | F24: Driving Time | G24: =G3/G6 -> 14.285714 | H24: =G24/24 -> 0.5952381
A25: 0.23 | B25: 111 kW | C25: 0.0092824074 | D25: 21.2 kWh | F25: Charger Detour Driving Time | G25: =ROUNDUP(G21,0)*((G4/G7)) -> 0.33333333 | H25: =G25/24 -> 0.013888889
A26: 0.24 | B26: 112 kW | C26: 0.0096527778 | D26: 22.1 kWh | F26: Charging Time | G26: =G21*G15 -> 2.8790727 | H26: =G26/24 -> 0.11996136
A27: 0.25 | B27: 112 kW | C27: 0.010011574 | D27: 23.0 kWh | F27: Combined Time | G27: =SUM(G24:G26) -> 17.49812 | H27: =G27/24 -> 0.72908835
A28: 0.26 | B28: 112 kW | C28: 0.010381944 | D28: 23.9 kWh
A29: 0.27 | B29: 112 kW | C29: 0.010752315 | D29: 24.8 kWh | F29: Fuel Cost Results | G29: Value
A30: 0.28 | B30: 112 kW | C30: 0.011122685 | D30: 25.8 kWh | F30: Start of Trip Battery Energy (kWh) | G30: =VALUE(LEFT((VLOOKUP(G8,$A$2:$D$102,4,FALSE)),LEN((VLOOKUP(G8,$A$2:$D$102,4,FALSE)))-4)) -> 92
A31: 0.29 | B31: 112 kW | C31: 0.011493056 | D31: 26.7 kWh | F31: Energy Recharged per DCFC Session (kWh) | G31: =VALUE(LEFT((VLOOKUP(G10,$A$2:$D$102,4,FALSE)),LEN((VLOOKUP(G10,$A$2:$D$102,4,FALSE)))-4))-VALUE(LEFT((VLOOKUP(G9,$A$2:$D$102,4,FALSE)),LEN((VLOOKUP(G9,$A$2:$D$102,4,FALSE)))-4)) -> 64.4
A32: 0.3 | B32: 112 kW | C32: 0.011851852 | D32: 27.6 kWh | F32: DCFC Recharged Energy (kWh) | G32: =(G21-G19)*G31 -> 234.03509
A33: 0.31 | B33: 113 kW | C33: 0.012222222 | D33: 28.5 kWh | F33: Home Charging Cost ($) | G33: =G30*G11 -> 15.5848
A34: 0.32 | B34: 112 kW | C34: 0.012592593 | D34: 29.4 kWh | F34: DCFC Charging Cost ($) | G34: =G32*G12 -> 107.65614
A35: 0.33 | B35: 107 kW | C35: 0.012962963 | D35: 30.4 kWh | F35: Total Fuel Costs ($) | G35: =SUM(G33:G34) -> 123.24094
A36: 0.34 | B36: 105 kW | C36: 0.013356481 | D36: 31.3 kWh
A37: 0.35 | B37: 103 kW | C37: 0.01375 | D37: 32.2 kWh | F37: Estimated Fuel Efficiency Results | G37: Value
A38: 0.36 | B38: 103 kW | C38: 0.014155093 | D38: 33.1 kWh | F38: ="Fuel Efficiency @"&$G$6& "mph (Miles/kWh)" -> Fuel Efficiency @70mph (Miles/kWh) | G38: =($J$4*($G$10-$G$9))/$G$31 -> 3.0978261
A39: 0.37 | B39: 103 kW | C39: 0.014548611 | D39: 34.0 kWh | F39: ="Fuel Efficiency @"&$G$6& "mph (kWh/100 mi)" -> Fuel Efficiency @70mph (kWh/100 mi) | G39: =(1/G38)*100 -> 32.280702
A40: 0.38 | B40: 102 kW | C40: 0.014953704 | D40: 35.0 kWh
...

Sheet Ford F-150 Lightning
A1: Battery State of Charge (%) | B1: Charging Speed (kW) | C1: Time (H:MM:SS) | D1: Energy Charged (kWh)
A2: 0 | B2: 80 kW | C2: 0 | D2: 0 kWh | F2: Scenario Parameters | G2: Value | I2: Vehicle Parameters
A3: 0.01 | B3: 145 kW | C3: 0.00038194444 | D3: 1.0 kWh | F3: Driving Distance (Miles) | G3: =Summary!H2 -> 1000 | I3: Vehicle Model | J3: Ford F-150 Lightning Standard Range
A4: 0.02 | B4: 153 kW | C4: 0.00068287037 | D4: 2.0 kWh | F4: Charger Detour Distance per Charge (Miles) | G4: =Summary!H3 -> 2.5 | I4: ="Vehicle Range @"&G6& "mph - Perfect Condition (Miles)" -> Vehicle Range @70mph - Perfect Condition (Miles) | J4: 196
A5: 0.03 | B5: 155 kW | C5: 0.00096064815 | D5: 2.9 kWh | F5: End of Trip Range (Miles) | G5: =Summary!H4 -> 25 | I5: Range Data Source | J5: https://evkx.net/models/ford/f150_lightning/f150_lightning_standard_range/rangeandconsumption/
A6: 0.04 | B6: 156 kW | C6: 0.00125 | D6: 3.9 kWh | F6: Highway Speed (MPH) | G6: =Summary!H5 -> 70 | I6: Charging Curve Data Source | J6: https://evkx.net/models/ford/f150_lightning/f150_lightning_standard_range/chargingcurve/
A7: 0.05 | B7: 156 kW | C7: 0.0015277778 | D7: 4.9 kWh | F7: City Speed (MPH) | G7: =Summary!H6 -> 30
A8: 0.06 | B8: 157 kW | C8: 0.0018055556 | D8: 5.9 kWh | F8: Start of Trip SoC (%) | G8: =Summary!H7 -> 1 | I8: Key Factors | J8: Values
A9: 0.07 | B9: 157 kW | C9: 0.0020833333 | D9: 6.9 kWh | F9: DCFC Beginning SoC (%) | G9: =Summary!H8 -> 0.1 | I9: =I4 -> Vehicle Range @70mph - Perfect Condition (Miles) | J9: =J4 -> 196
A10: 0.08 | B10: 158 kW | C10: 0.0023726852 | D10: 7.8 kWh | F10: DCFC Ending SoC (%) | G10: =Summary!H9 -> 0.8 | I10: =F38 -> Fuel Efficiency @70mph (Miles/kWh) | J10: =G38 -> 2
A11: 0.09 | B11: 158 kW | C11: 0.002650463 | D11: 8.8 kWh | F11: Home Charging Cost ($/kWh) | G11: =Summary!H10 -> 0.1694 | I11: =F42 -> Average Charging Speed 10%-80% (kW) | J11: =G42 -> 118.71831
A12: 0.1 | B12: 158 kW | C12: 0.0029282407 | D12: 9.8 kWh | F12: DCFC Charging Cost ($/kWh) | G12: =Summary!H11 -> 0.46
A13: 0.11 | B13: 160 kW | C13: 0.0031944444 | D13: 10.8 kWh
A14: 0.12 | B14: 129 kW | C14: 0.0035069444 | D14: 11.8 kWh | F14: Time Per Charging Session | G14: Time (Decimal) | H14: Time (Duration)
A15: 0.13 | B15: 129 kW | C15: 0.0038425926 | D15: 12.7 kWh | F15: =TEXT(G9,"00%")&"-"&TEXT(G10,"00%")&" Charging Time" -> 10%-80% Charging Time | G15: =(VLOOKUP(G10,$A$2:$D$102,3,FALSE)-VLOOKUP(G9,$A$2:$D$102,3,FALSE))*24 -> 0.62555556 | H15: =G15/24 -> 0.026064815
A16: 0.14 | B16: 129 kW | C16: 0.0041782407 | D16: 13.7 kWh
A17: 0.15 | B17: 129 kW | C17: 0.004525463 | D17: 14.7 kWh | F17: Charging Calculations | G17: Value
A18: 0.16 | B18: 128 kW | C18: 0.0048611111 | D18: 15.7 kWh | F18: ="Number of Charges for Driving "&TEXT(G3,"###,##0")&" Miles" -> Number of Charges for Driving 1,000 Miles | G18: =MAX(((G3-(J4*G8))/((J4*(G10-G9)))),0) -> 5.8600583
A19: 0.17 | B19: 128 kW | C19: 0.0052083333 | D19: 16.7 kWh | F19: ="Number of Charges for "&G5&" Miles Remaing" -> Number of Charges for 25 Miles Remaing | G19: =(G5/((J4*(G10-G9)))) -> 0.18221574
A20: 0.18 | B20: 128 kW | C20: 0.0055555556 | D20: 17.6 kWh | F20: Number of Charges for Detour Distance | G20: =IF(SUM((ROUNDUP(G18+G19,0)*(G4/(J4*(G10-G9)))),G18:G19)>ROUNDUP(G18+G19,0),ROUNDUP(G18+G19+1,0)*(G4/(J4*(G10-G9))),ROUNDUP(G18+G19,0)*(G4/(J4*(G10-G9)))) -> 0.12755102
A21: 0.19 | B21: 128 kW | C21: 0.0058912037 | D21: 18.6 kWh | F21: Total Number of Charges | G21: =SUM(G18:G20) -> 6.1698251
A22: 0.2 | B22: 127 kW | C22: 0.0062384259 | D22: 19.6 kWh
A23: 0.21 | B23: 127 kW | C23: 0.0065856481 | D23: 20.6 kWh | F23: Time Results | G23: Time (Decimal) | H23: Time (Duration)
A24: 0.22 | B24: 127 kW | C24: 0.0069328704 | D24: 21.6 kWh | F24: Driving Time | G24: =G3/G6 -> 14.285714 | H24: =G24/24 -> 0.5952381
A25: 0.23 | B25: 126 kW | C25: 0.0072800926 | D25: 22.5 kWh | F25: Charger Detour Driving Time | G25: =ROUNDUP(G21,0)*((G4/G7)) -> 0.58333333 | H25: =G25/24 -> 0.024305556
A26: 0.24 | B26: 126 kW | C26: 0.0076273148 | D26: 23.5 kWh | F26: Charging Time | G26: =G21*G15 -> 3.8595684 | H26: =G26/24 -> 0.16081535
A27: 0.25 | B27: 125 kW | C27: 0.007974537 | D27: 24.5 kWh | F27: Combined Time | G27: =SUM(G24:G26) -> 18.728616 | H27: =G27/24 -> 0.780359
A28: 0.26 | B28: 125 kW | C28: 0.0083333333 | D28: 25.5 kWh
A29: 0.27 | B29: 125 kW | C29: 0.0086805556 | D29: 26.5 kWh | F29: Fuel Cost Results | G29: Value
A30: 0.28 | B30: 124 kW | C30: 0.0090277778 | D30: 27.4 kWh | F30: Start of Trip Battery Energy (kWh) | G30: =VALUE(LEFT((VLOOKUP(G8,$A$2:$D$102,4,FALSE)),LEN((VLOOKUP(G8,$A$2:$D$102,4,FALSE)))-4)) -> 98
A31: 0.29 | B31: 124 kW | C31: 0.0093865741 | D31: 28.4 kWh | F31: Energy Recharged per DCFC Session (kWh) | G31: =VALUE(LEFT((VLOOKUP(G10,$A$2:$D$102,4,FALSE)),LEN((VLOOKUP(G10,$A$2:$D$102,4,FALSE)))-4))-VALUE(LEFT((VLOOKUP(G9,$A$2:$D$102,4,FALSE)),LEN((VLOOKUP(G9,$A$2:$D$102,4,FALSE)))-4)) -> 68.6
A32: 0.3 | B32: 124 kW | C32: 0.0097453704 | D32: 29.4 kWh | F32: DCFC Recharged Energy (kWh) | G32: =(G21-G19)*G31 -> 410.75
A33: 0.31 | B33: 123 kW | C33: 0.010092593 | D33: 30.4 kWh | F33: Home Charging Cost ($) | G33: =G30*G11 -> 16.6012
A34: 0.32 | B34: 123 kW | C34: 0.010451389 | D34: 31.4 kWh | F34: DCFC Charging Cost ($) | G34: =G32*G12 -> 188.945
A35: 0.33 | B35: 122 kW | C35: 0.010810185 | D35: 32.3 kWh | F35: Total Fuel Costs ($) | G35: =SUM(G33:G34) -> 205.5462
A36: 0.34 | B36: 122 kW | C36: 0.011168981 | D36: 33.3 kWh
A37: 0.35 | B37: 122 kW | C37: 0.011527778 | D37: 34.3 kWh | F37: Estimated Fuel Efficiency Results | G37: Value
A38: 0.36 | B38: 121 kW | C38: 0.011898148 | D38: 35.3 kWh | F38: ="Fuel Efficiency @"&$G$6& "mph (Miles/kWh)" -> Fuel Efficiency @70mph (Miles/kWh) | G38: =($J$4*($G$10-$G$9))/$G$31 -> 2
A39: 0.37 | B39: 121 kW | C39: 0.012256944 | D39: 36.3 kWh | F39: ="Fuel Efficiency @"&$G$6& "mph (kWh/100 mi)" -> Fuel Efficiency @70mph (kWh/100 mi) | G39: =(1/G38)*100 -> 50
A40: 0.38 | B40: 121 kW | C40: 0.012615741 | D40: 37.2 kWh
...

Sheet Toyota bZ4X
A1: Battery State of Charge (%) | B1: Charging Speed (kW) | C1: Time (H:MM:SS) | D1: Energy Charged (kWh)
A2: 0 | B2: 50 kW | C2: 0 | D2: 0 kWh | F2: Scenario Parameters | G2: Value | I2: Vehicle Parameters
A3: 0.01 | B3: 81 kW | C3: 0.00042824074 | D3: 0.6 kWh | F3: Driving Distance (Miles) | G3: =Summary!H2 -> 1000 | I3: Vehicle Model | J3: Toyota bZ4X AWD
A4: 0.02 | B4: 82 kW | C4: 0.00078703704 | D4: 1.3 kWh | F4: Charger Detour Distance per Charge (Miles) | G4: =Summary!H3 -> 2.5 | I4: ="Vehicle Range @"&G6& "mph - Perfect Condition (Miles)" -> Vehicle Range @70mph - Perfect Condition (Miles) | J4: 190
A5: 0.03 | B5: 83 kW | C5: 0.0011342593 | D5: 1.9 kWh | F5: End of Trip Range (Miles) | G5: =Summary!H4 -> 25 | I5: Range Data Source | J5: https://evkx.net/models/toyota/bz4x/bz4x_awd/rangeandconsumption/
A6: 0.04 | B6: 84 kW | C6: 0.0014699074 | D6: 2.6 kWh | F6: Highway Speed (MPH) | G6: =Summary!H5 -> 70 | I6: Charging Curve Data Source | J6: https://evkx.net/models/toyota/bz4x/bz4x_awd/chargingcurve/
A7: 0.05 | B7: 85 kW | C7: 0.0018171296 | D7: 3.2 kWh | F7: City Speed (MPH) | G7: =Summary!H6 -> 30
A8: 0.06 | B8: 86 kW | C8: 0.0021527778 | D8: 3.8 kWh | F8: Start of Trip SoC (%) | G8: =Summary!H7 -> 1 | I8: Key Factors | J8: Values
A9: 0.07 | B9: 87 kW | C9: 0.0024768519 | D9: 4.5 kWh | F9: DCFC Beginning SoC (%) | G9: =Summary!H8 -> 0.1 | I9: =I4 -> Vehicle Range @70mph - Perfect Condition (Miles) | J9: =J4 -> 190
A10: 0.08 | B10: 88 kW | C10: 0.0028125 | D10: 5.1 kWh | F10: DCFC Ending SoC (%) | G10: =Summary!H9 -> 0.8 | I10: =F38 -> Fuel Efficiency @70mph (Miles/kWh) | J10: =G38 -> 2.96875
A11: 0.09 | B11: 89 kW | C11: 0.0031365741 | D11: 5.8 kWh | F11: Home Charging Cost ($/kWh) | G11: =Summary!H10 -> 0.1694 | I11: =F42 -> Average Charging Speed 10%-80% (kW) | J11: =G42 -> 89.126761
A12: 0.1 | B12: 90 kW | C12: 0.0034490741 | D12: 6.4 kWh | F12: DCFC Charging Cost ($/kWh) | G12: =Summary!H11 -> 0.46
A13: 0.11 | B13: 90 kW | C13: 0.0037731481 | D13: 7.0 kWh
A14: 0.12 | B14: 111 kW | C14: 0.0040625 | D14: 7.7 kWh | F14: Time Per Charging Session | G14: Time (Decimal) | H14: Time (Duration)
A15: 0.13 | B15: 121 kW | C15: 0.0043055556 | D15: 8.3 kWh | F15: =TEXT(G9,"00%")&"-"&TEXT(G10,"00%")&" Charging Time" -> 10%-80% Charging Time | G15: =(VLOOKUP(G10,$A$2:$D$102,3,FALSE)-VLOOKUP(G9,$A$2:$D$102,3,FALSE))*24 -> 0.64111111 | H15: =G15/24 -> 0.026712963
A16: 0.14 | B16: 129 kW | C16: 0.004537037 | D16: 9.0 kWh
A17: 0.15 | B17: 132 kW | C17: 0.0047569444 | D17: 9.6 kWh | F17: Charging Calculations | G17: Value
A18: 0.16 | B18: 133 kW | C18: 0.0049652778 | D18: 10.2 kWh | F18: ="Number of Charges for Driving "&TEXT(G3,"###,##0")&" Miles" -> Number of Charges for Driving 1,000 Miles | G18: =MAX(((G3-(J4*G8))/((J4*(G10-G9)))),0) -> 6.0902256
A19: 0.17 | B19: 135 kW | C19: 0.0051851852 | D19: 10.9 kWh | F19: ="Number of Charges for "&G5&" Miles Remaing" -> Number of Charges for 25 Miles Remaing | G19: =(G5/((J4*(G10-G9)))) -> 0.18796992
A20: 0.18 | B20: 134 kW | C20: 0.0053935185 | D20: 11.5 kWh | F20: Number of Charges for Detour Distance | G20: =IF(SUM((ROUNDUP(G18+G19,0)*(G4/(J4*(G10-G9)))),G18:G19)>ROUNDUP(G18+G19,0),ROUNDUP(G18+G19+1,0)*(G4/(J4*(G10-G9))),ROUNDUP(G18+G19,0)*(G4/(J4*(G10-G9)))) -> 0.13157895
A21: 0.19 | B21: 133 kW | C21: 0.0056134259 | D21: 12.2 kWh | F21: Total Number of Charges | G21: =SUM(G18:G20) -> 6.4097744
A22: 0.2 | B22: 135 kW | C22: 0.0058217593 | D22: 12.8 kWh
A23: 0.21 | B23: 134 kW | C23: 0.0060416667 | D23: 13.4 kWh | F23: Time Results | G23: Time (Decimal) | H23: Time (Duration)
A24: 0.22 | B24: 132 kW | C24: 0.00625 | D24: 14.1 kWh | F24: Driving Time | G24: =G3/G6 -> 14.285714 | H24: =G24/24 -> 0.5952381
A25: 0.23 | B25: 134 kW | C25: 0.0064699074 | D25: 14.7 kWh | F25: Charger Detour Driving Time | G25: =ROUNDUP(G21,0)*((G4/G7)) -> 0.58333333 | H25: =G25/24 -> 0.024305556
A26: 0.24 | B26: 134 kW | C26: 0.0066782407 | D26: 15.4 kWh | F26: Charging Time | G26: =G21*G15 -> 4.1093776 | H26: =G26/24 -> 0.17122407
A27: 0.25 | B27: 137 kW | C27: 0.0068981481 | D27: 16.0 kWh | F27: Combined Time | G27: =SUM(G24:G26) -> 18.978425 | H27: =G27/24 -> 0.79076772
A28: 0.26 | B28: 135 kW | C28: 0.0071064815 | D28: 16.6 kWh
A29: 0.27 | B29: 136 kW | C29: 0.0073148148 | D29: 17.3 kWh | F29: Fuel Cost Results | G29: Value
A30: 0.28 | B30: 133 kW | C30: 0.0075347222 | D30: 17.9 kWh | F30: Start of Trip Battery Energy (kWh) | G30: =VALUE(LEFT((VLOOKUP(G8,$A$2:$D$102,4,FALSE)),LEN((VLOOKUP(G8,$A$2:$D$102,4,FALSE)))-4)) -> 64
A31: 0.29 | B31: 132 kW | C31: 0.0077430556 | D31: 18.6 kWh | F31: Energy Recharged per DCFC Session (kWh) | G31: =VALUE(LEFT((VLOOKUP(G10,$A$2:$D$102,4,FALSE)),LEN((VLOOKUP(G10,$A$2:$D$102,4,FALSE)))-4))-VALUE(LEFT((VLOOKUP(G9,$A$2:$D$102,4,FALSE)),LEN((VLOOKUP(G9,$A$2:$D$102,4,FALSE)))-4)) -> 44.8
A32: 0.3 | B32: 129 kW | C32: 0.007962963 | D32: 19.2 kWh | F32: DCFC Recharged Energy (kWh) | G32: =(G21-G19)*G31 -> 278.73684
A33: 0.31 | B33: 126 kW | C33: 0.0081944444 | D33: 19.8 kWh | F33: Home Charging Cost ($) | G33: =G30*G11 -> 10.8416
A34: 0.32 | B34: 123 kW | C34: 0.0084259259 | D34: 20.5 kWh | F34: DCFC Charging Cost ($) | G34: =G32*G12 -> 128.21895
A35: 0.33 | B35: 120 kW | C35: 0.0086574074 | D35: 21.1 kWh | F35: Total Fuel Costs ($) | G35: =SUM(G33:G34) -> 139.06055
A36: 0.34 | B36: 119 kW | C36: 0.008900463 | D36: 21.8 kWh
A37: 0.35 | B37: 113 kW | C37: 0.0091435185 | D37: 22.4 kWh | F37: Estimated Fuel Efficiency Results | G37: Value
A38: 0.36 | B38: 111 kW | C38: 0.0093981481 | D38: 23.0 kWh | F38: ="Fuel Efficiency @"&$G$6& "mph (Miles/kWh)" -> Fuel Efficiency @70mph (Miles/kWh) | G38: =($J$4*($G$10-$G$9))/$G$31 -> 2.96875
A39: 0.37 | B39: 109 kW | C39: 0.0096643519 | D39: 23.7 kWh | F39: ="Fuel Efficiency @"&$G$6& "mph (kWh/100 mi)" -> Fuel Efficiency @70mph (kWh/100 mi) | G39: =(1/G38)*100 -> 33.684211
A40: 0.38 | B40: 106 kW | C40: 0.0099305556 | D40: 24.3 kWh
...
